Workbook

Sheet Content Calendar
A1: # | B1: الأسبوع | C1: التاريخ | D1: اليوم | E1: المنصات | F1: الفورمات | G1: شكل النشر | H1: المحور (Pillar) | I1: الفكرة | J1: المسؤول | K1: المراجع | L1: الكابشن | M1: الهاشتاجات | N1: رابط التصميم/الفيديو | O1: الحالة
A2: 1 | B2: 1 | C2: 46319 | D2: السبت | E2: LinkedIn + Facebook + Instagram + TikTok | F2: نص + صورة | G2: بوست صورة على LinkedIn + FB + IG + TikTok (Photo Mode) | H2: اكتشف التجربة | I2: تعريف: «رِحال... نكتشف التجربة، نحجزها، ونعيشها» | J2: ساندي | K2: عبدالرحمن | O2: لم يبدأ
A3: 2 | B3: 1 | C3: 46320 | D3: الأحد | E3: YouTube Shorts + Instagram + TikTok + Facebook | F3: فيديو Reel | G3: نفس الـ Reel على YouTube Shorts + IG + TikTok + FB (من غير Watermark + ميوزك ترند) | H3: اكتشف التجربة | I3: تيزر: مشاهد من (صحرا، جبل، أكل، حرف) مع سؤال «إيه آخر تجربة مختلفة عشتها؟» | J3: يمنى | K3: عبدالرحمن | O3: لم يبدأ
A4: 3 | B4: 1 | C4: 46322 | D4: الثلاثاء | E4: LinkedIn + Facebook + Instagram + TikTok | F4: كاروسيل | G4: كاروسيل على LinkedIn + FB + IG + TikTok (Photo Mode + ميوزك ترند) | H4: نصايح ومعلومات | I4: المشكلة: 5 مواقف بتخليك مش لاقي تجربة تتحجز بسهولة | J4: صفا | K4: عبدالرحمن | O4: لم يبدأ
A5: 4 | B5: 1 | C5: 46324 | D5: الخميس | E5: Instagram + Facebook | F5: Poll/ستوري | G5: ستوري بملصق Poll على IG + استفتاء على صفحة FB | H5: تفاعل | I5: بتحب أنهي نوع؟ Camping / Hiking / أكل / حرف | J5: شذا | K5: عبدالرحمن | O5: لم يبدأ
A6: 5 | B6: 1 | C6: 46325 | D6: الجمعة | E6: LinkedIn + Facebook + Instagram + TikTok | F6: نص + صورة | G6: بوست صورة على LinkedIn + FB + IG + TikTok (Photo Mode) | H6: نصايح ومعلومات | I6: كيف رِحال بتشتغل؟ 3 خطوات: اكتشف ← احجز ← عيش | J6: عبدالرحمن | K6: الفريق كله | O6: لم يبدأ
A7: 6 | B7: 2 | C7: 46326 | D7: السبت | E7: LinkedIn + Facebook + Instagram + TikTok | F7: كاروسيل | G7: كاروسيل على LinkedIn + FB + IG + TikTok (Photo Mode + ميوزك ترند) | H7: اكتشف التجربة | I7: 5 تجارب تنفع تعملها في الشتا في مصر | J7: صفا | K7: عبدالرحمن | O7: لم يبدأ
A8: 7 | B8: 2 | C8: 46327 | D8: الأحد | E8: YouTube Shorts + Instagram + TikTok + Facebook | F8: فيديو Reel | G8: نفس الـ Reel على YouTube Shorts + IG + TikTok + FB (من غير Watermark + ميوزك ترند) | H8: اكتشف التجربة | I8: يوم كامل في تجربة Camping (لقطات سريعة) | J8: يمنى | K8: عبدالرحمن | O8: لم يبدأ
A9: 8 | B9: 2 | C9: 46329 | D9: الثلاثاء | E9: LinkedIn + Facebook + Instagram + TikTok | F9: نص + صورة | G9: بوست صورة على LinkedIn + FB + IG + TikTok (Photo Mode) | H9: اكتشف التجربة | I9: Spotlight: تجربة هايكنج مع وصف وسعر تقريبي | J9: ساندي | K9: عبدالرحمن | O9: لم يبدأ
A10: 9 | B10: 2 | C10: 46331 | D10: الخميس | E10: Instagram + Facebook | F10: Poll/ستوري | G10: ستوري بملصق Poll على IG + استفتاء على صفحة FB | H10: تفاعل | I10: Quiz: شخصيتك إيه؟ مغامر ولا رايق ولا بتاع أكل؟ | J10: شذا | K10: عبدالرحمن | O10: لم يبدأ
A11: 10 | B11: 2 | C11: 46332 | D11: الجمعة | E11: YouTube Shorts + Instagram + TikTok + Facebook | F11: فيديو Reel | G11: نفس الـ Reel على YouTube Shorts + IG + TikTok + FB (من غير Watermark + ميوزك ترند) | H11: ثقة وآراء | I11: Behind the scenes: إزاي بنختار التجارب؟ | J11: عبدالرحمن | K11: الفريق كله | O11: لم يبدأ
A12: 11 | B12: 3 | C12: 46333 | D12: السبت | E12: LinkedIn + Facebook + Instagram + TikTok | F12: نص + صورة | G12: بوست صورة على LinkedIn + FB + IG + TikTok (Photo Mode) | H12: أصحاب التجارب | I12: دعوة: عندك تجربة؟ انضم لرِحال ووصّل لعملاء أكتر | J12: ساندي | K12: عبدالرحمن | O12: لم يبدأ
A13: 12 | B13: 3 | C13: 46334 | D13: الأحد | E13: LinkedIn + Facebook + Instagram + TikTok | F13: كاروسيل | G13: كاروسيل على LinkedIn + FB + IG + TikTok (Photo Mode + ميوزك ترند) | H13: أصحاب التجارب | I13: ليه تنضم كـ Host؟ (وصول، حجز سهل، عمولة بس على الحجز) | J13: صفا | K13: عبدالرحمن | O13: لم يبدأ
... A29: 28 | B29: 6 | C29: 46356 | D29: الإثنين | E29: LinkedIn + Facebook + Instagram + TikTok | F29: نص + صورة | G29: بوست صورة على LinkedIn + FB + IG + TikTok (Photo Mode) | H29: عروض وحجز | I29: «الشتا بدأ... احجز تجربتك الجاية» + CTA للحجز | J29: عبدالرحمن | K29: الفريق كله | O29: لم يبدأ

Sheet Summary
A1: حسب المنصة (البوست الواحد بيتحسب على كل منصة بينزل عليها)
A2: البند | B2: عدد البوستات
A3: Instagram | B3: =COUNTIF('Content Calendar'!$E$2:$E$29,"*Instagram*") -> 27
A4: Facebook | B4: =COUNTIF('Content Calendar'!$E$2:$E$29,"*Facebook*") -> 27
A5: TikTok | B5: =COUNTIF('Content Calendar'!$E$2:$E$29,"*TikTok*") -> 25
A6: LinkedIn | B6: =COUNTIF('Content Calendar'!$E$2:$E$29,"*LinkedIn*") -> 17
A7: YouTube Shorts | B7: =COUNTIF('Content Calendar'!$E$2:$E$29,"*YouTube Shorts*") -> 7
A8: عدد البوستات الفريدة | B8: =COUNTA('Content Calendar'!$A$2:$A$29) -> 28
A10: حسب الفورمات
A11: البند | B11: عدد البوستات
A12: نص + صورة | B12: =COUNTIF('Content Calendar'!$F$2:$F$29,A12) -> 9
A13: فيديو Reel | B13: =COUNTIF('Content Calendar'!$F$2:$F$29,A13) -> 7
A14: كاروسيل | B14: =COUNTIF('Content Calendar'!$F$2:$F$29,A14) -> 7
A15: Poll/ستوري | B15: =COUNTIF('Content Calendar'!$F$2:$F$29,A15) -> 3
A16: إنفوجراف | B16: =COUNTIF('Content Calendar'!$F$2:$F$29,A16) -> 1
A17: تحدي تفاعلي | B17: =COUNTIF('Content Calendar'!$F$2:$F$29,A17) -> 1
A18: الإجمالي | B18: =SUM(B12:B17) -> 28
A20: حسب المحور
A21: البند | B21: عدد البوستات
A22: اكتشف التجربة | B22: =COUNTIF('Content Calendar'!$H$2:$H$29,A22) -> 9
A23: نصايح ومعلومات | B23: =COUNTIF('Content Calendar'!$H$2:$H$29,A23) -> 4
A24: أصحاب التجارب | B24: =COUNTIF('Content Calendar'!$H$2:$H$29,A24) -> 4
A25: ثقة وآراء | B25: =COUNTIF('Content Calendar'!$H$2:$H$29,A25) -> 5
A26: تفاعل | B26: =COUNTIF('Content Calendar'!$H$2:$H$29,A26) -> 4
A27: عروض وحجز | B27: =COUNTIF('Content Calendar'!$H$2:$H$29,A27) -> 2
A28: الإجمالي | B28: =SUM(B22:B27) -> 28
A30: حسب المسؤول
A31: البند | B31: عدد البوستات
A32: عبدالرحمن | B32: =COUNTIF('Content Calendar'!$J$2:$J$29,A32) -> 6
A33: ساندي | B33: =COUNTIF('Content Calendar'!$J$2:$J$29,A33) -> 6
A34: يمنى | B34: =COUNTIF('Content Calendar'!$J$2:$J$29,A34) -> 7
A35: صفا | B35: =COUNTIF('Content Calendar'!$J$2:$J$29,A35) -> 6
A36: شذا | B36: =COUNTIF('Content Calendar'!$J$2:$J$29,A36) -> 3
A37: الإجمالي | B37: =SUM(B32:B36) -> 28
A39: حسب الحالة
A40: البند | B40: عدد البوستات
A41: لم يبدأ | B41: =COUNTIF('Content Calendar'!$O$2:$O$29,A41) -> 28
A42: قيد التنفيذ | B42: =COUNTIF('Content Calendar'!$O$2:$O$29,A42) -> 0
A43: جاهز للمراجعة | B43: =COUNTIF('Content Calendar'!$O$2:$O$29,A43) -> 0
A44: تم النشر | B44: =COUNTIF('Content Calendar'!$O$2:$O$29,A44) -> 0
...

Sheet Team & Roles
A1: الاسم | B1: الدور في الفريق | C1: الدور في الـ Content Calendar
A2: عبدالرحمن يوسف إبراهيم علي | B2: Team Leader: التنسيق، إدارة GitHub وGoogle Drive، المراجعة النهائية والتسليم | C2: مراجعة وموافقة على كل البوستات + بوست أسبوعي باسمه (جمعة، وإثنين 30/11)، وبوستاته بيراجعها الفريق كله
A3: صفا محمد عبدالفتاح السرسي | B3: Situation Analysis: أبحاث السوق، الجمهور المستهدف، تحليل المنافسين | C3: الأفكار والريسيرش (ترندات، منافسين، معلومات) + الكاروسيلات
A4: ساندي محمد عبدالله أبوزيد | B4: Objectives & Strategy: أهداف SMART، الـ Positioning، نموذج العمولة | C4: الكابشنز والـ CTA وصوت البراند + بوستات النص والصورة
A5: شذا علاء عنتر حجاج | B5: Tactics: خطة المحتوى، قنوات السوشيال، أفكار الحملات | C5: مسؤولة الـ Content Plan والنشر والجدولة + بوستات التفاعل
A6: يمنى عماد مصطفى شند | B6: Action & Control: الجدول الزمني، الميزانية، الـ KPIs، تتبع الأداء | C6: التصميم/المونتاج + تتبع الـ KPIs أسبوعياً
A8: المشرف: د. تامر المغازي

Sheet Weekly KPIs
A1: تتبع الأداء الأسبوعي (تملاه يمنى) - الخلايا الزرقاء = إدخال يدوي، السوداء = معادلات
A2: الأسبوع | B2: من | C2: إلى | D2: عدد البوستات (مخطط) | E2: Reach | F2: Engagements | G2: Saves + Shares | H2: Clicks على اللينك | I2: استفسارات/حجوزات | J2: Engagement Rate | K2: TikTok Views
A3: مثال (مش بيتحسب) | E3: 12000 | F3: 540 | G3: 95 | H3: 60 | I3: 4 | J3: =IFERROR(F3/E3,0) -> 0.045 | K3: 8000
A4: 1 | B4: 46319 | C4: 46325 | D4: =COUNTIF('Content Calendar'!$B$2:$B$29,A4) -> 5 | J4: =IFERROR(F4/E4,0) -> 0
A5: 2 | B5: 46326 | C5: 46332 | D5: =COUNTIF('Content Calendar'!$B$2:$B$29,A5) -> 5 | J5: =IFERROR(F5/E5,0) -> 0
A6: 3 | B6: 46333 | C6: 46339 | D6: =COUNTIF('Content Calendar'!$B$2:$B$29,A6) -> 5 | J6: =IFERROR(F6/E6,0) -> 0
A7: 4 | B7: 46340 | C7: 46346 | D7: =COUNTIF('Content Calendar'!$B$2:$B$29,A7) -> 5 | J7: =IFERROR(F7/E7,0) -> 0
A8: 5 | B8: 46347 | C8: 46353 | D8: =COUNTIF('Content Calendar'!$B$2:$B$29,A8) -> 5 | J8: =IFERROR(F8/E8,0) -> 0
A9: 6 | B9: 46354 | C9: 46356 | D9: =COUNTIF('Content Calendar'!$B$2:$B$29,A9) -> 3 | J9: =IFERROR(F9/E9,0) -> 0
A10: الإجمالي | D10: =SUM(D4:D9) -> 28 | E10: =SUM(E4:E9) -> 0 | F10: =SUM(F4:F9) -> 0 | G10: =SUM(G4:G9) -> 0 | H10: =SUM(H4:H9) -> 0 | I10: =SUM(I4:I9) -> 0 | J10: =IFERROR(F10/E10,0) -> 0 | K10: =SUM(K4:K9) -> 0
